<?xml version="1.0" encoding="utf-8"?>
<!-- =================================================================================== -->
<!-- |    This document was autogenerated by xacro from ur5_joint_limited_robot.urdf.xacro | -->
<!-- |    EDITING THIS FILE BY HAND IS NOT RECOMMENDED                                 | -->
<!-- =================================================================================== -->
<robot name="ur5">
  <gazebo>
    <plugin filename="libgazebo_ros_control.so" name="ros_control">
      <!--robotNamespace>/</robotNamespace-->
      <!--robotSimType>gazebo_ros_control/DefaultRobotHWSim</robotSimType-->
    </plugin>
    <!--
    <plugin name="gazebo_ros_power_monitor_controller" filename="libgazebo_ros_power_monitor.so">
      <alwaysOn>true</alwaysOn>
      <updateRate>1.0</updateRate>
      <timeout>5</timeout>
      <powerStateTopic>power_state</powerStateTopic>
      <powerStateRate>10.0</powerStateRate>
      <fullChargeCapacity>87.78</fullChargeCapacity>     
      <dischargeRate>-474</dischargeRate>
      <chargeRate>525</chargeRate>
      <dischargeVoltage>15.52</dischargeVoltage>
      <chargeVoltage>16.41</chargeVoltage>
    </plugin>
-->
  </gazebo>
  <!-- measured from model -->
  <!--property name="shoulder_height" value="0.089159" /-->
  <!--property name="shoulder_offset" value="0.13585" /-->
  <!-- shoulder_offset - elbow_offset + wrist_1_length = 0.10915 -->
  <!--property name="upper_arm_length" value="0.42500" /-->
  <!--property name="elbow_offset" value="0.1197" /-->
  <!-- CAD measured -->
  <!--property name="forearm_length" value="0.39225" /-->
  <!--property name="wrist_1_length" value="0.093" /-->
  <!-- CAD measured -->
  <!--property name="wrist_2_length" value="0.09465" /-->
  <!-- In CAD this distance is 0.930, but in the spec it is 0.09465 -->
  <!--property name="wrist_3_length" value="0.0823" /-->
  <!-- manually measured -->
  <link name="base_link">
    <visual>
      <geometry>
        <mesh filename="ur5_meshes/visual_obj/base.dae"/>
      </geometry>
      <material name="LightGrey">
        <color rgba="0.7 0.7 0.7 1.0"/>
      </material>
    </visual>
    <collision>
      <geometry>
        <mesh filename="ur5_meshes/collision_obj/base.stl.obj"/>
      </geometry>
    </collision>
    <inertial>
      <mass value="4.0"/>
      <origin rpy="0 0 0" xyz="0.0 0.0 0.0"/>
      <inertia ixx="0.00443333156" ixy="0.0" ixz="0.0" iyy="0.00443333156" iyz="0.0" izz="0.0072"/>
    </inertial>
  </link>
  <joint name="shoulder_pan_joint" type="revolute">
    <parent link="base_link"/>
    <child link="shoulder_link"/>
    <origin rpy="0.0 0.0 0.0" xyz="0.0 0.0 0.089159"/>
    <axis xyz="0 0 1"/>
    <limit effort="150.0" lower="-3.14159265359" upper="3.14159265359" velocity="3.15"/>
    <dynamics rotor_inertia="1.0"/>
  </joint>
  <link name="shoulder_link">
    <visual>
      <geometry>
        <mesh filename="ur5_meshes/visual_obj/shoulder.dae"/>
      </geometry>
      <material name="LightGrey">
        <color rgba="0.7 0.7 0.7 1.0"/>
      </material>
    </visual>
    <collision>
      <geometry>
        <mesh filename="ur5_meshes/collision_obj/shoulder.stl.obj"/>
      </geometry>
    </collision>
    <inertial>
      <mass value="3.7"/>
      <origin rpy="0 0 0" xyz="0.0 0.0 0.0"/>
      <inertia ixx="0.010267495893" ixy="0.0" ixz="0.0" iyy="0.010267495893" iyz="0.0" izz="0.00666"/>
    </inertial>
  </link>
  <joint name="shoulder_lift_joint" type="revolute">
    <parent link="shoulder_link"/>
    <child link="upper_arm_link"/>
    <origin rpy="0.0 1.57079632679 0.0" xyz="0.0 0.13585 0.0"/>
    <axis xyz="0 1 0"/>
    <limit effort="150.0" lower="-3.14159265359" upper="3.14159265359" velocity="3.15"/>
    <dynamics rotor_inertia="1.0"/>
  </joint>
  <link name="upper_arm_link">
    <visual>
      <geometry>
        <mesh filename="ur5_meshes/visual_obj/upperarm.dae"/>
      </geometry>
      <material name="LightGrey">
        <color rgba="0.7 0.7 0.7 1.0"/>
      </material>
    </visual>
    <collision>
      <geometry>
        <mesh filename="ur5_meshes/collision_obj/upperarm.stl.obj"/>
      </geometry>
    </collision>
    <inertial>
      <mass value="8.393"/>
      <origin rpy="0 0 0" xyz="0.0 0.0 0.28"/>
      <inertia ixx="0.22689067591" ixy="0.0" ixz="0.0" iyy="0.22689067591" iyz="0.0" izz="0.0151074"/>
    </inertial>
  </link>
  <joint name="elbow_joint" type="revolute">
    <parent link="upper_arm_link"/>
    <child link="forearm_link"/>
    <origin rpy="0.0 0.0 0.0" xyz="0.0 -0.1197 0.425"/>
    <axis xyz="0 1 0"/>
    <limit effort="150.0" lower="-3.14159265359" upper="3.14159265359" velocity="3.15"/>
    <dynamics rotor_inertia="1.0"/>
  </joint>
  <link name="forearm_link">
    <visual>
      <geometry>
        <mesh filename="ur5_meshes/visual_obj/forearm.dae"/>
      </geometry>
      <material name="LightGrey">
        <color rgba="0.7 0.7 0.7 1.0"/>
      </material>
    </visual>
    <collision>
      <geometry>
        <mesh filename="ur5_meshes/collision_obj/forearm.stl.obj"/>
      </geometry>
    </collision>
    <inertial>
      <mass value="2.275"/>
      <origin rpy="0 0 0" xyz="0.0 0.0 0.196125"/>
      <inertia ixx="0.0312167910289" ixy="0.0" ixz="0.0" iyy="0.0312167910289" iyz="0.0" izz="0.004095"/>
    </inertial>
  </link>
  <joint name="wrist_1_joint" type="revolute">
    <parent link="forearm_link"/>
    <child link="wrist_1_link"/>
    <origin rpy="0.0 1.57079632679 0.0" xyz="0.0 0.0 0.39225"/>
    <axis xyz="0 1 0"/>
    <limit effort="28.0" lower="-3.14159265359" upper="3.14159265359" velocity="3.2"/>
    <dynamics rotor_inertia="1.0"/>
  </joint>
  <link name="wrist_1_link">
    <visual>
      <geometry>
        <mesh filename="ur5_meshes/visual_obj/wrist1.dae"/>
      </geometry>
      <material name="LightGrey">
        <color rgba="0.7 0.7 0.7 1.0"/>
      </material>
    </visual>
    <collision>
      <geometry>
        <mesh filename="ur5_meshes/collision_obj/wrist1.stl.obj"/>
      </geometry>
    </collision>
    <inertial>
      <mass value="1.219"/>
      <origin rpy="0 0 0" xyz="0.0 0.093 0.0"/>
      <inertia ixx="0.00255989897604" ixy="0.0" ixz="0.0" iyy="0.00255989897604" iyz="0.0" izz="0.0021942"/>
    </inertial>
  </link>
  <joint name="wrist_2_joint" type="revolute">
    <parent link="wrist_1_link"/>
    <child link="wrist_2_link"/>
    <origin rpy="0.0 0.0 0.0" xyz="0.0 0.093 0.0"/>
    <axis xyz="0 0 1"/>
    <limit effort="28.0" lower="-3.14159265359" upper="3.14159265359" velocity="3.2"/>
    <dynamics rotor_inertia="1.0"/>
  </joint>
  <link name="wrist_2_link">
    <visual>
      <geometry>
        <mesh filename="ur5_meshes/visual_obj/wrist2.dae"/>
      </geometry>
      <material name="LightGrey">
        <color rgba="0.7 0.7 0.7 1.0"/>
      </material>
    </visual>
    <collision>
      <geometry>
        <mesh filename="ur5_meshes/collision_obj/wrist2.stl.obj"/>
      </geometry>
    </collision>
    <inertial>
      <mass value="1.219"/>
      <origin rpy="0 0 0" xyz="0.0 0.0 0.09465"/>
      <inertia ixx="0.00255989897604" ixy="0.0" ixz="0.0" iyy="0.00255989897604" iyz="0.0" izz="0.0021942"/>
    </inertial>
  </link>
  <joint name="wrist_3_joint" type="revolute">
    <parent link="wrist_2_link"/>
    <child link="wrist_3_link"/>
    <origin rpy="0.0 0.0 0.0" xyz="0.0 0.0 0.09465"/>
    <axis xyz="0 1 0"/>
    <limit effort="28.0" lower="-3.14159265359" upper="3.14159265359" velocity="3.2"/>
    <dynamics rotor_inertia="1.0"/>
  </joint>
  <link name="wrist_3_link">
    <visual>
      <geometry>
        <mesh filename="ur5_meshes/visual_obj/wrist3.dae"/>
      </geometry>
      <material name="LightGrey">
        <color rgba="0.7 0.7 0.7 1.0"/>
      </material>
    </visual>
    <collision>
      <geometry>
        <mesh filename="ur5_meshes/collision_obj/wrist3.stl.obj"/>
      </geometry>
    </collision>
    <inertial>
      <mass value="0.1879"/>
      <origin rpy="1.57079632679 0 0" xyz="0.0 0.06505 0.0"/>
      <inertia ixx="8.46958911216e-05" ixy="0.0" ixz="0.0" iyy="8.46958911216e-05" iyz="0.0" izz="0.0001321171875"/>
    </inertial>
  </link>
  <joint name="ee_fixed_joint" type="fixed">
    <parent link="wrist_3_link"/>
    <child link="ee_link"/>
    <origin rpy="0.0 0.0 1.57079632679" xyz="0.0 0.0823 0.0"/>
  </joint>
  <link name="ee_link">
    <collision>
      <geometry>
        <box size="0.01 0.01 0.01"/>
      </geometry>
      <origin rpy="0 0 0" xyz="-0.01 0 0"/>
    </collision>
  </link>
  <transmission name="shoulder_pan_trans">
    <type>transmission_interface/SimpleTransmission</type>
    <joint name="shoulder_pan_joint">
      <hardwareInterface>hardware_interface/PositionJointInterface</hardwareInterface>
    </joint>
    <actuator name="shoulder_pan_motor">
      <mechanicalReduction>1</mechanicalReduction>
    </actuator>
  </transmission>
  <transmission name="shoulder_lift_trans">
    <type>transmission_interface/SimpleTransmission</type>
    <joint name="shoulder_lift_joint">
      <hardwareInterface>hardware_interface/PositionJointInterface</hardwareInterface>
    </joint>
    <actuator name="shoulder_lift_motor">
      <mechanicalReduction>1</mechanicalReduction>
    </actuator>
  </transmission>
  <transmission name="elbow_trans">
    <type>transmission_interface/SimpleTransmission</type>
    <joint name="elbow_joint">
      <hardwareInterface>hardware_interface/PositionJointInterface</hardwareInterface>
    </joint>
    <actuator name="elbow_motor">
      <mechanicalReduction>1</mechanicalReduction>
    </actuator>
  </transmission>
  <transmission name="wrist_1_trans">
    <type>transmission_interface/SimpleTransmission</type>
    <joint name="wrist_1_joint">
      <hardwareInterface>hardware_interface/PositionJointInterface</hardwareInterface>
    </joint>
    <actuator name="wrist_1_motor">
      <mechanicalReduction>1</mechanicalReduction>
    </actuator>
  </transmission>
  <transmission name="wrist_2_trans">
    <type>transmission_interface/SimpleTransmission</type>
    <joint name="wrist_2_joint">
      <hardwareInterface>hardware_interface/PositionJointInterface</hardwareInterface>
    </joint>
    <actuator name="wrist_2_motor">
      <mechanicalReduction>1</mechanicalReduction>
    </actuator>
  </transmission>
  <transmission name="wrist_3_trans">
    <type>transmission_interface/SimpleTransmission</type>
    <joint name="wrist_3_joint">
      <hardwareInterface>hardware_interface/PositionJointInterface</hardwareInterface>
    </joint>
    <actuator name="wrist_3_motor">
      <mechanicalReduction>1</mechanicalReduction>
    </actuator>
  </transmission>
  <gazebo reference="shoulder_link">
    <selfCollide>true</selfCollide>
  </gazebo>
  <gazebo reference="upper_arm_link">
    <selfCollide>true</selfCollide>
  </gazebo>
  <gazebo reference="forearm_link">
    <selfCollide>true</selfCollide>
  </gazebo>
  <gazebo reference="wrist_1_link">
    <selfCollide>true</selfCollide>
  </gazebo>
  <gazebo reference="wrist_3_link">
    <selfCollide>true</selfCollide>
  </gazebo>
  <gazebo reference="wrist_2_link">
    <selfCollide>true</selfCollide>
  </gazebo>
  <gazebo reference="ee_link">
    <selfCollide>true</selfCollide>
  </gazebo>
  <!-- ROS base_link to UR 'Base' Coordinates transform -->
  <link name="base"/>
  <joint name="base_link-base_fixed_joint" type="fixed">
    <!-- NOTE: this rotation is only needed as long as base_link itself is
                 not corrected wrt the real robot (ie: rotated over 180
                 degrees)
      -->
    <origin rpy="0 0 -3.14159265359" xyz="0 0 0"/>
    <parent link="base_link"/>
    <child link="base"/>
  </joint>
  <!-- Frame coincident with all-zeros TCP on UR controller -->
  <link name="tool0"/>
  <joint name="wrist_3_link-tool0_fixed_joint" type="fixed">
    <origin rpy="-1.57079632679 0 0" xyz="0 0.0823 0"/>
    <parent link="wrist_3_link"/>
    <child link="tool0"/>
  </joint>

  <!-- ly add: Flange -->
  <!-- <origin
      xyz="-0.0071009 0.0068801 0.063001"
      rpy="0 0 0" /> -->

  <link
    name="Flange_base_link">
    <!-- <inertial>
      <origin
        xyz="-0.0071009 0.0068801 0.063001"
        rpy="0 0 0" />
      <mass
        value="0.22469" />
      <inertia
        ixx="5.4203E-05"
        ixy="4.3107E-08"
        ixz="-3.4558E-10"
        iyy="0.00010297"
        iyz="-4.2502E-13"
        izz="5.3523E-05" />
    </inertial>
    <visual>
      <origin
        xyz="0 0 0"
        rpy="0 0 0" />
      <geometry>
        <mesh
          filename="Flange_meshes/base_link.STL" />
      </geometry>
      <material
        name="">
        <color
          rgba="0.2 0.2 0.2 1" />
      </material>
    </visual>
    <collision>
      <origin
        xyz="0 0 0"
        rpy="0 0 0" />
      <geometry>
        <mesh
          filename="Flange_meshes/base_link.obj" />
      </geometry>
    </collision> -->
  </link>
  <!-- TCP_simulation_link -->
  <!-- <link name="TCP_simulation_link">
  </link> -->


  <joint name="tool02Flange_fixed_joint" type="fixed">
    <origin rpy="0 0 0" xyz="0 0 0"/>   <!-- xyz="0.0 0 0.01"-->
    <parent link="tool0"/>
    <child link="Flange_base_link"/>
  </joint>
  <!-- ly add: Flange -->

  <!-- ly add: Allegro Hand -->
  <!-- <joint name="Flange2TCP_simulation_fixed_joint" type="fixed">
    <origin rpy="0 0 0" xyz="0 0 0"/>
    <parent link="Flange_base_link"/>
    <child link="TCP_simulation_link"/>
  </joint> -->

  <joint name="Flange2hand_fixed_joint" type="fixed">
    <origin rpy="0 0 0" xyz="0 0 0"/>      <!-- xyz="0.0091 0 0.013313"-->
    <parent link="Flange_base_link"/>
    <child link="Allegro_base_link"/>
  </joint>

  <!-- PALM -->
  <link name="Allegro_base_link">
    <visual>
      <geometry>
        <mesh filename="allegro_meshes/base_link.STL"/>
      </geometry>
      <origin rpy="0 0 0" xyz="0.0091 0 0.105 "/>  <!-- ly modified: 0 > -0.050987 -->
      <material name="black">
        <color rgba="0.2 0.2 0.2 1"/>
      </material>
    </visual>
    <collision>
      <material name="">
          <contact name="finger"/>
      </material>
      <origin rpy="0 0 0" xyz="0.0091 0 0.105"/> <!-- ly modified: -0.0475 > 0.003487 -->
      <geometry>
        <mesh filename="allegro_meshes/palm_sim.obj"/>
      </geometry>
    </collision>
    <inertial>
      <origin rpy="0 0 0" xyz="0 0 0.0475"/>
      <mass value="0.4154"/>
      <inertia ixx="1e-4" ixy="0.0" ixz="0.0" iyy="1e-4" iyz="0.0" izz="1e-4"/>
    </inertial>
  </link>
  <!-- ============================================================================= -->
  <!-- FINGERS -->
  <!-- RIGHT HAND due to which finger is number 0 -->
  <!-- for LEFT HAND switch the sign of the **offset_origin_y** and **finger_angle_r** parameters-->
  <!-- [LINK 0, 4, 8] -->
  <link name="link_0.0">
    <visual>
      <geometry>
        <mesh filename="allegro_meshes/link_0.0.STL"/>
      </geometry>
      <material name="black"/>
    </visual>
    <inertial>
      <mass value="0.01458"/>
      <origin rpy="0 0 0" xyz="0 0 0"/>
      <inertia ixx="1.2454165645792e-06" ixy="0.0" ixz="0.0" iyy="7.9340473333292e-07" iyz="0.0" izz="1.2454165645792e-06"/>
    </inertial>
  </link>
  <joint name="joint_0.0" type="revolute">
    <axis xyz="0 0 1"/>
    <limit effort="0.7" lower="-0.47" upper="0.47" velocity="7"/>
    <parent link="Allegro_base_link"/>
    <child link="link_0.0"/>
    <origin rpy="-0.08726646255 0 0" xyz="0.0091 0.0435 0.103458"/> <!-- ly modified: -0.001542 > 0.049445 -->
    <dynamics damping="3.90180564" friction="10"/>
  </joint>
  <!-- [LINK 1, 5, 9] -->
  <link name="link_1.0">
    <visual>
      <geometry>
        <mesh filename="allegro_meshes/link_1.0.STL"/>
      </geometry>
      <material name="black"/>
    </visual>
    <collision>
      <material name="">
          <contact name="finger"/>
      </material>
      <geometry>
        <box size="0.0196 0.0275 0.04"/>
      </geometry>
      <origin rpy="0 0 0" xyz="0 0 0.018"/>
    </collision>
    <inertial>
      <mass value="0.0796"/>
      <origin rpy="0 0 0" xyz="0 0 0"/>
      <inertia ixx="9.7467635416707e-05" ixy="2.1068775e-05" ixz="1.072946875e-05" iyy="3.0268382083292e-05" iyz="2.956078125e-05" izz="9.7467635416707e-05"/>
    </inertial>
  </link>
  <joint name="joint_1.0" type="revolute">
    <limit effort="0.7" lower="-0.196" upper="1.61" velocity="7"/>
    <axis xyz="0 1 0"/>
    <parent link="link_0.0"/>
    <child link="link_1.0"/>
    <origin xyz="0 0 0.0164"/>
    <dynamics damping="0.01291585" friction="5"/>
  </joint>
  <!-- [LINK 2, 6, 10]-->
  <link name="link_2.0">
    <visual>
      <geometry>
        <mesh filename="allegro_meshes/link_2.0.STL"/>
      </geometry>
      <material name="black"/>
    </visual>
    <collision>
      <material name="">
          <contact name="finger"/>
      </material>
      <geometry>
        <box size="0.0196 0.0275 0.0344"/>
      </geometry>
      <origin rpy="0 0 0" xyz="0 0 0.0122"/>
    </collision>
    <inertial>
      <mass value="0.04349"/>
      <origin rpy="0 0 0" xyz="0 0 0"/>
      <inertia ixx="3.2337449958292e-05" ixy="8.182608e-06" ixz="5.859940625e-06" iyy="1.6531193291707e-05" iyz="1.14807e-05" izz="3.2337449958292e-05"/>
    </inertial>
  </link>
  <joint name="joint_2.0" type="revolute">
    <axis xyz="0 1 0"/>
    <limit effort="0.7" lower="-0.174" upper="1.709" velocity="7"/>
    <parent link="link_1.0"/>
    <child link="link_2.0"/>
    <origin xyz="0 0 0.054"/>
    <dynamics damping="6.66517925" friction="10"/>
  </joint>
  <!-- [LINK 3, 7, 11] -->
  <link name="link_3.0">
    <visual>
      <geometry>
        <mesh filename="allegro_meshes/link_3.0.STL"/>
      </geometry>
      <material name="black"/>
    </visual>
    <collision>
      <material name="">
          <contact name="finger"/>
      </material>
      <geometry>
        <box size="0.0196 0.0275 0.0117"/>
      </geometry>
      <origin rpy="0 0 0" xyz="0 0 0.00985"/>
    </collision>
    <inertial>
      <mass value="0.01103"/>
      <origin rpy="0 0 0" xyz="0 0 0"/>
      <inertia ixx="5.7590288e-06" ixy="1.5385608e-06" ixz="1.58466e-06" iyy="4.4704072e-06" iyz="2.158695e-06" izz="5.7590288e-06"/>
    </inertial>
  </link>
  <joint name="joint_3.0" type="revolute">
    <axis xyz="0 1 0"/>
    <limit effort="0.7" lower="-0.227" upper="1.618" velocity="7"/>
    <parent link="link_2.0"/>
    <child link="link_3.0"/>
    <origin xyz="0 0 0.0384"/>
    <dynamics damping="9.79553223" friction="12"/>
  </joint>
  <!-- [FINGER TIP] -->
  <link name="link_3.0_tip">
    <visual>
      <geometry>
        <mesh filename="allegro_meshes/link_3.0_tip.STL"/>
      </geometry>
      <material name="white">
        <color rgba=".9 .9 .9 1"/>
      </material>
    </visual>
    <collision>
      <material name="">
          <contact name="finger"/>
      </material>
      <geometry>
        <mesh filename="allegro_meshes/tip.obj"/>
      </geometry>
    </collision>
    <inertial>
      <mass value="0.02058"/>
      <origin rpy="0 0 0" xyz="0 0 0"/>
      <inertia ixx="1.1858e-06" ixy="0" ixz="0" iyy="1.1858e-06" iyz="0" izz="1.1858e-06"/>
    </inertial>
  </link>
  <joint name="joint_3.0_tip" type="fixed">
    <parent link="link_3.0"/>
    <child link="link_3.0_tip"/>
    <origin rpy="0 0 0" xyz="0 0 0.0267"/>
  </joint>
  <!-- [LINK 0, 4, 8] -->
  <link name="link_4.0">
    <visual>
      <geometry>
        <mesh filename="allegro_meshes/link_0.0.STL"/>
      </geometry>
      <material name="black"/>
    </visual>
    <inertial>
      <mass value="0.01458"/>
      <origin rpy="0 0 0" xyz="0 0 0"/>
      <inertia ixx="1.2454165645792e-06" ixy="0.0" ixz="0.0" iyy="7.9340473333292e-07" iyz="0.0" izz="1.2454165645792e-06"/>
    </inertial>
  </link>
  <joint name="joint_4.0" type="revolute">
    <axis xyz="0 0 1"/>
    <limit effort="0.7" lower="-0.47" upper="0.47" velocity="7"/>
    <parent link="Allegro_base_link"/>
    <child link="link_4.0"/>
    <origin rpy="0.0 0 0" xyz="0.0091 0 0.1057"/>  <!-- ly modified: 0.0007 > 0.051687 -->
    <dynamics damping="2.68129516" friction="10"/>
  </joint>
  <!-- [LINK 1, 5, 9] -->
  <link name="link_5.0">
    <visual>
      <geometry>
        <mesh filename="allegro_meshes/link_1.0.STL"/>
      </geometry>
      <material name="black"/>
    </visual>
    <collision>
      <material name="">
          <contact name="finger"/>
      </material>
      <geometry>
        <box size="0.0196 0.0275 0.04"/>
      </geometry>
      <origin rpy="0 0 0" xyz="0 0 0.018"/>
    </collision>
    <inertial>
      <mass value="0.0796"/>
      <origin rpy="0 0 0" xyz="0 0 0"/>
      <inertia ixx="9.7467635416707e-05" ixy="2.1068775e-05" ixz="1.072946875e-05" iyy="3.0268382083292e-05" iyz="2.956078125e-05" izz="9.7467635416707e-05"/>
    </inertial>
  </link>
  <joint name="joint_5.0" type="revolute">
    <limit effort="0.7" lower="-0.196" upper="1.61" velocity="7"/>
    <axis xyz="0 1 0"/>
    <parent link="link_4.0"/>
    <child link="link_5.0"/>
    <origin xyz="0 0 0.0164"/>
    <dynamics damping="0.11413904" friction="5"/>
  </joint>
  <!-- [LINK 2, 6, 10]-->
  <link name="link_6.0">
    <visual>
      <geometry>
        <mesh filename="allegro_meshes/link_2.0.STL"/>
      </geometry>
      <material name="black"/>
    </visual>
    <collision>
      <material name="">
          <contact name="finger"/>
      </material>
      <geometry>
        <box size="0.0196 0.0275 0.0344"/>
      </geometry>
      <origin rpy="0 0 0" xyz="0 0 0.0122"/>
    </collision>
    <inertial>
      <mass value="0.04349"/>
      <origin rpy="0 0 0" xyz="0 0 0"/>
      <inertia ixx="3.2337449958292e-05" ixy="8.182608e-06" ixz="5.859940625e-06" iyy="1.6531193291707e-05" iyz="1.14807e-05" izz="3.2337449958292e-05"/>
    </inertial>
  </link>
  <joint name="joint_6.0" type="revolute">
    <axis xyz="0 1 0"/>
    <limit effort="0.7" lower="-0.174" upper="1.709" velocity="7"/>
    <parent link="link_5.0"/>
    <child link="link_6.0"/>
    <origin xyz="0 0 0.054"/>
    <dynamics damping="8.03685093" friction="10"/>
  </joint>
  <!-- [LINK 3, 7, 11] -->
  <link name="link_7.0">
    <visual>
      <geometry>
        <mesh filename="allegro_meshes/link_3.0.STL"/>
      </geometry>
      <material name="black"/>
    </visual>
    <collision>
      <material name="">
          <contact name="finger"/>
      </material>
      <geometry>
        <box size="0.0196 0.0275 0.0117"/>
      </geometry>
      <origin rpy="0 0 0" xyz="0 0 0.00985"/>
    </collision>
    <inertial>
      <mass value="0.01103"/>
      <origin rpy="0 0 0" xyz="0 0 0"/>
      <inertia ixx="5.7590288e-06" ixy="1.5385608e-06" ixz="1.58466e-06" iyy="4.4704072e-06" iyz="2.158695e-06" izz="5.7590288e-06"/>
    </inertial>
  </link>
  <joint name="joint_7.0" type="revolute">
    <axis xyz="0 1 0"/>
    <limit effort="0.7" lower="-0.227" upper="1.618" velocity="7"/>
    <parent link="link_6.0"/>
    <child link="link_7.0"/>
    <origin xyz="0 0 0.0384"/>
    <dynamics damping="0.82893139" friction="12"/>
  </joint>
  <!-- [FINGER TIP] -->
  <link name="link_7.0_tip">
    <visual>
      <geometry>
        <mesh filename="allegro_meshes/link_3.0_tip.STL"/>
      </geometry>
      <material name="white">
        <color rgba=".9 .9 .9 1"/>
      </material>
    </visual>
    <collision>
      <material name="">
          <contact name="finger"/>
      </material>
      <geometry>
        <mesh filename="allegro_meshes/tip.obj"/>
      </geometry>
    </collision>
    <inertial>
      <mass value="0.02058"/>
      <origin rpy="0 0 0" xyz="0 0 0"/>
      <inertia ixx="1.1858e-06" ixy="0" ixz="0" iyy="1.1858e-06" iyz="0" izz="1.1858e-06"/>
    </inertial>
  </link>
  <joint name="joint_7.0_tip" type="fixed">
    <parent link="link_7.0"/>
    <child link="link_7.0_tip"/>
    <origin rpy="0 0 0" xyz="0 0 0.0267"/>
  </joint>
  <!-- [LINK 0, 4, 8] -->
  <link name="link_8.0">
    <visual>
      <geometry>
        <mesh filename="allegro_meshes/link_0.0.STL"/>
      </geometry>
      <material name="black"/>
    </visual>
    <inertial>
      <mass value="0.01458"/>
      <origin rpy="0 0 0" xyz="0 0 0"/>
      <inertia ixx="1.2454165645792e-06" ixy="0.0" ixz="0.0" iyy="7.9340473333292e-07" iyz="0.0" izz="1.2454165645792e-06"/>
    </inertial>
  </link>
  <joint name="joint_8.0" type="revolute">
    <axis xyz="0 0 1"/>
    <limit effort="0.7" lower="-0.47" upper="0.47" velocity="7"/>
    <parent link="Allegro_base_link"/>
    <child link="link_8.0"/>
    <origin rpy="0.08726646255 0 0" xyz="0.0091 -0.0435 0.103458"/> <!-- ly modified: -0.001542 > 0.049445 -->
    <dynamics damping="5.3809495" friction="10"/>
  </joint>
  <!-- [LINK 1, 5, 9] -->
  <link name="link_9.0">
    <visual>
      <geometry>
        <mesh filename="allegro_meshes/link_1.0.STL"/>
      </geometry>
      <material name="black"/>
    </visual>
    <collision>
      <material name="">
          <contact name="finger"/>
      </material>
      <geometry>
        <box size="0.0196 0.0275 0.04"/>
      </geometry>
      <origin rpy="0 0 0" xyz="0 0 0.018"/>
    </collision>
    <inertial>
      <mass value="0.0796"/>
      <origin rpy="0 0 0" xyz="0 0 0"/>
      <inertia ixx="9.7467635416707e-05" ixy="2.1068775e-05" ixz="1.072946875e-05" iyy="3.0268382083292e-05" iyz="2.956078125e-05" izz="9.7467635416707e-05"/>
    </inertial>
  </link>
  <joint name="joint_9.0" type="revolute">
    <limit effort="0.7" lower="-0.196" upper="1.61" velocity="7"/>
    <axis xyz="0 1 0"/>
    <parent link="link_8.0"/>
    <child link="link_9.0"/>
    <origin xyz="0 0 0.0164"/>
    <dynamics damping="0.10022587" friction="5"/>
  </joint>
  <!-- [LINK 2, 6, 10]-->
  <link name="link_10.0">
    <visual>
      <geometry>
        <mesh filename="allegro_meshes/link_2.0.STL"/>
      </geometry>
      <material name="black"/>
    </visual>
    <collision>
      <material name="">
          <contact name="finger"/>
      </material>
      <geometry>
        <box size="0.0196 0.0275 0.0344"/>
      </geometry>
      <origin rpy="0 0 0" xyz="0 0 0.0122"/>
    </collision>
    <inertial>
      <mass value="0.04349"/>
      <origin rpy="0 0 0" xyz="0 0 0"/>
      <inertia ixx="3.2337449958292e-05" ixy="8.182608e-06" ixz="5.859940625e-06" iyy="1.6531193291707e-05" iyz="1.14807e-05" izz="3.2337449958292e-05"/>
    </inertial>
  </link>
  <joint name="joint_10.0" type="revolute">
    <axis xyz="0 1 0"/>
    <limit effort="0.7" lower="-0.174" upper="1.709" velocity="7"/>
    <parent link="link_9.0"/>
    <child link="link_10.0"/>
    <origin xyz="0 0 0.054"/>
    <dynamics damping="8.46683884" friction="10"/>
  </joint>
  <!-- [LINK 3, 7, 11] -->
  <link name="link_11.0">
    <visual>
      <geometry>
        <mesh filename="allegro_meshes/link_3.0.STL"/>
      </geometry>
      <material name="black"/>
    </visual>
    <collision>
      <material name="">
          <contact name="finger"/>
      </material>
      <geometry>
        <box size="0.0196 0.0275 0.0117"/>
      </geometry>
      <origin rpy="0 0 0" xyz="0 0 0.00985"/>
    </collision>
    <inertial>
      <mass value="0.01103"/>
      <origin rpy="0 0 0" xyz="0 0 0"/>
      <inertia ixx="5.7590288e-06" ixy="1.5385608e-06" ixz="1.58466e-06" iyy="4.4704072e-06" iyz="2.158695e-06" izz="5.7590288e-06"/>
    </inertial>
  </link>
  <joint name="joint_11.0" type="revolute">
    <axis xyz="0 1 0"/>
    <limit effort="0.7" lower="-0.227" upper="1.618" velocity="7"/>
    <parent link="link_10.0"/>
    <child link="link_11.0"/>
    <origin xyz="0 0 0.0384"/>
    <dynamics damping="5.9256773" friction="12"/>
  </joint>
  <!-- [FINGER TIP] -->
  <link name="link_11.0_tip">
    <visual>
      <geometry>
        <mesh filename="allegro_meshes/link_3.0_tip.STL"/>
      </geometry>
      <material name="white">
        <color rgba=".9 .9 .9 1"/>
      </material>
    </visual>
    <collision>
      <material name="">
          <contact name="finger"/>
      </material>
      <geometry>
        <mesh filename="allegro_meshes/tip.obj"/>
      </geometry>
    </collision>
    <inertial>
      <mass value="0.02058"/>
      <origin rpy="0 0 0" xyz="0 0 0"/>
      <inertia ixx="1.1858e-06" ixy="0" ixz="0" iyy="1.1858e-06" iyz="0" izz="1.1858e-06"/>
    </inertial>
  </link>
  <joint name="joint_11.0_tip" type="fixed">
    <parent link="link_11.0"/>
    <child link="link_11.0_tip"/>
    <origin rpy="0 0 0" xyz="0 0 0.0267"/>
  </joint>
  <!-- THUMB -->
  <!-- [LINK 12] -->
  <link name="link_12.0">
    <visual>
      <geometry>
        <!--<mesh filename="allegro_meshes/link_12.0_right.STL"/>-->
        <mesh filename="allegro_meshes/link_12.0_right.STL"/>  <!-- ly modified -->
      </geometry>
      <material name="black">
        <color rgba=".2 .2 .2 1"/>
      </material>
      <!--<origin rpy="3.1415926518 0 0" xyz="0 0 0"/>--> <!-- ly modified -->
    </visual>
    <inertial>
      <mass value="0.0272"/>
      <origin rpy="0 0 0" xyz="0 0 0"/>
      <inertia ixx="2.9204875333281e-05" ixy="1.105892788e-05" ixz="8.26381424e-06" iyy="2.2066167317281e-05" iyz="1.05028924e-05" izz="2.9204875333281e-05"/>
    </inertial>
  </link>
  <joint name="joint_12.0" type="revolute">
    <axis xyz="-1 0 0"/>
    <limit effort="0.7" lower="0.263" upper="1.396" velocity="7"/>
    <parent link="Allegro_base_link"/>
    <child link="link_12.0"/>
    <origin rpy="0 -1.65806278845 -1.5707963259" xyz="-0.0091 0.019333 0.059013"/> <!-- ly modified: -0.045987 > 0.005 -->
    <dynamics damping="0." friction="10"/>
  </joint>
  <!-- [LINK 13] -->
  <link name="link_13.0">
    <visual>
      <geometry>
        <!-- <mesh filename="allegro_meshes/link_13.0.STL"/> -->
        <mesh filename="allegro_meshes/link_13.0.STL"/>  <!-- ly modified -->
      </geometry>
      <material name="black">
        <color rgba=".2 .2 .2 1"/>
      </material>
    </visual>
    <collision>
      <material name="">
          <contact name="finger"/>
      </material>
      <geometry>
        <box size="0.0196 0.0275 0.0107"/>
      </geometry>
      <origin rpy="0 0 0" xyz="0 0 0.00905"/>
    </collision>
    <inertial>
      <mass value="0.01836"/>
      <origin rpy="0 0 0" xyz="0 0 0"/>
      <inertia ixx="6.5461908726718e-06" ixy="1.592510241e-06" ixz="2.474239075e-06" iyy="6.9799554323281e-06" iyz="2.23438936875e-06" izz="6.5461908726718e-06"/>
    </inertial>
  </link>
  <joint name="joint_13.0" type="revolute">
    <axis xyz="0 0 1"/>
    <limit effort="0.7" lower="-0.105" upper="1.163" velocity="7"/>
    <parent link="link_12.0"/>
    <child link="link_13.0"/>
    <origin xyz="-0.027 0.005 0.0399"/>
    <dynamics damping="0." friction="5"/>
  </joint>
  <!-- [LINK 14] -->
  <link name="link_14.0">
    <visual>
      <geometry>
        <mesh filename="allegro_meshes/link_14.0.STL"/>
      </geometry>
      <material name="black">
                </material>
    </visual>
    <collision>
      <material name="">
          <contact name="finger"/>
      </material>
      <geometry>
        <box size="0.0196 0.0275 0.035"/>
      </geometry>
      <origin rpy="0 0 0" xyz="0 0 0.0257"/>
    </collision>
    <inertial>
      <mass value="0.05863"/>
      <origin rpy="0 0 0" xyz="0 0 0"/>
      <inertia ixx="6.6416881713281e-05" ixy="1.476755924e-05" ixz="7.9009315e-06" iyy="2.2288933313281e-05" iyz="2.071978975e-05" izz="6.6416881713281e-05"/>
    </inertial>
  </link>
  <joint name="joint_14.0" type="revolute">
    <axis xyz="0 1 0"/>
    <limit effort="0.7" lower="-0.189" upper="1.644" velocity="7"/>
    <parent link="link_13.0"/>
    <child link="link_14.0"/>
    <origin xyz="0 0 0.0177"/>
    <dynamics damping="0.9443478" friction="10"/>
  </joint>
  <!-- [LINK 15] -->
  <link name="link_15.0">
    <visual>
      <geometry>
        <mesh filename="allegro_meshes/link_15.0.STL"/>
      </geometry>
      <material name="black">
                </material>
    </visual>
    <collision>
      <material name="">
          <contact name="finger"/>
      </material>
      <geometry>
        <box size="0.0196 0.0275 0.0253"/>
      </geometry>
      <origin rpy="0 0 0" xyz="0 0 0.01815"/>
    </collision>
    <inertial>
      <mass value="0.05987"/>
      <origin rpy="0 0 0" xyz="0 0 0"/>
      <inertia ixx="5.0799135645281e-05" ixy="1.2408923268e-05" ixz="8.0672669e-06" iyy="2.27581740414718e-5" iyz="1.7410479075e-5" izz="5.0799135645281e-05"/>
    </inertial>
  </link>
  <joint name="joint_15.0" type="revolute">
    <axis xyz="0 1 0"/>
    <limit effort="0.7" lower="-0.162" upper="1.719" velocity="7"/>
    <parent link="link_14.0"/>
    <child link="link_15.0"/>
    <origin xyz="0 0 0.0514"/>
    <dynamics damping="2.1758244" friction="12"/>
  </joint>
  <!-- [FINGER TIP] -->
  <link name="link_15.0_tip">
    <visual>
      <geometry>
        <mesh filename="allegro_meshes/link_15.0_tip.STL"/>
      </geometry>
      <material name="white">
        <color rgba=".9 .9 .9 1"/>
      </material>
    </visual>
    <collision>
      <material name="">
          <contact name="finger"/>
      </material>
      <geometry>
        <mesh filename="allegro_meshes/tip.obj"/>
      </geometry>
      <origin rpy="0 0 0" xyz="0 0 0"/>
    </collision>
    <inertial>
      <mass value="0.0259224"/>
      <origin rpy="0 0 0" xyz="0 0 0"/>
      <inertia ixx="1.493624e-06" ixy="0" ixz="0" iyy="1.493624e-06" iyz="0" izz="1.493624e-06"/>
    </inertial>
  </link>
  <joint name="joint_15.0_tip" type="fixed">
    <parent link="link_15.0"/>
    <child link="link_15.0_tip"/>
    <origin rpy="0 0 0" xyz="0 0 0.0423"/>
  </joint>
  <!-- ly add: Allegro Hand -->

  <!-- ly add: platform -->
  <link name="world"></link>
  <link
    name="platform_base_link">
    <inertial>
      <origin
        xyz="0.23866 -0.0018349 0.30694"
        rpy="0 0 0" />
      <mass
        value="100" />
      <inertia
        ixx="1.65006434644742"
        ixy="-0.000408772605278627"
        ixz="0.0483178937212822"
        iyy="4.02315462619992"
        iyz="-0.000120223922225659"
        izz="5.22125227955039" />
    </inertial>
    <visual>
      <origin
        xyz="0 0 0"
        rpy="-1.57 0.0 -1.57" />
      <geometry>
        <mesh
          filename="platform_meshes/base_link.STL" />
      </geometry>
      <material
        name="">
        <color
          rgba="1 1 1 1" />
      </material>
    </visual>
  </link>

  <!-- 0.55 0.75152 0.0 -->
  <joint name="worldur5_to_base" type="fixed">
    <parent link="world"/>
    <child link="platform_base_link"/>
    <origin rpy="0.0 0.0 0.0" xyz="0.0 0.0 0.0"/>
    <!-- <origin rpy="-1.57 0.0 -1.57" xyz="0.0 0.0 0.0"/> -->
  </joint>

  <link name="Link_1"> </link>
  <joint name="Link_1" type="fixed">
    <origin xyz="0 0 0.771" rpy="0 0 0" />
    <parent link="platform_base_link" />
    <child link="Link_1" />
    <axis xyz="0 0 0" />
  </joint>


  <!-- <link name="world"/> -->
  <joint name="platform2ur5_joint" type="fixed">
    <parent link="Link_1"/>
    <child link="base_link"/>
    <origin rpy="0.0 0.0 -1.57" xyz="0.0 0.0 0.0"/>
  </joint>
</robot>
